2024-01-09T18:12:27,973 Using pip 23.2.1 from C:\Users\Iman Babaei\git\testACP\venv\Lib\site-packages\pip (python 3.12)
2024-01-09T18:12:27,973 Non-user install because user site-packages disabled
2024-01-09T18:12:28,075 Created temporary directory: C:\Users\Iman Babaei\AppData\Local\Temp\pip-build-tracker-ao4fw73b
2024-01-09T18:12:28,075 Initialized build tracking at C:\Users\Iman Babaei\AppData\Local\Temp\pip-build-tracker-ao4fw73b
2024-01-09T18:12:28,075 Created build tracker: C:\Users\Iman Babaei\AppData\Local\Temp\pip-build-tracker-ao4fw73b
2024-01-09T18:12:28,075 Entered build tracker: C:\Users\Iman Babaei\AppData\Local\Temp\pip-build-tracker-ao4fw73b
2024-01-09T18:12:28,075 Created temporary directory: C:\Users\Iman Babaei\AppData\Local\Temp\pip-install-ri9ffsg4
2024-01-09T18:12:28,075 Created temporary directory: C:\Users\Iman Babaei\AppData\Local\Temp\pip-ephem-wheel-cache-_kr76w02
2024-01-09T18:12:28,111 1 location(s) to search for versions of azure-service-connector-passwordless:
2024-01-09T18:12:28,111 * https://pypi.org/simple/azure-service-connector-passwordless/
2024-01-09T18:12:28,111 Fetching project page and analyzing links: https://pypi.org/simple/azure-service-connector-passwordless/
2024-01-09T18:12:28,111 Getting page https://pypi.org/simple/azure-service-connector-passwordless/
2024-01-09T18:12:28,111 Found index url https://pypi.org/simple/
2024-01-09T18:12:29,027 Could not fetch URL https://pypi.org/simple/azure-service-connector-passwordless/: 404 Client Error: Not Found for url: https://pypi.org/simple/azure-service-connector-passwordless/ - skipping
2024-01-09T18:12:29,027 Skipping link: not a file: https://pypi.org/simple/azure-service-connector-passwordless/
2024-01-09T18:12:29,027 Given no hashes to check 0 links for project 'azure-service-connector-passwordless': discarding no candidates
2024-01-09T18:12:29,027 ERROR: Could not find a version that satisfies the requirement azure-service-connector-passwordless (from versions: none)
2024-01-09T18:12:29,031 ERROR: No matching distribution found for azure-service-connector-passwordless
2024-01-09T18:12:29,032 Exception information:
2024-01-09T18:12:29,032 Traceback (most recent call last):
2024-01-09T18:12:29,032   File "C:\Users\Iman Babaei\git\testACP\venv\Lib\site-packages\pip\_vendor\resolvelib\resolvers.py", line 397, in resolve
2024-01-09T18:12:29,032     self._add_to_criteria(self.state.criteria, r, parent=None)
2024-01-09T18:12:29,032   File "C:\Users\Iman Babaei\git\testACP\venv\Lib\site-packages\pip\_vendor\resolvelib\resolvers.py", line 174, in _add_to_criteria
2024-01-09T18:12:29,032     raise RequirementsConflicted(criterion)
2024-01-09T18:12:29,032 pip._vendor.resolvelib.resolvers.RequirementsConflicted: Requirements conflict: SpecifierRequirement('azure-service-connector-passwordless')
2024-01-09T18:12:29,032 
2024-01-09T18:12:29,032 During handling of the above exception, another exception occurred:
2024-01-09T18:12:29,032 
2024-01-09T18:12:29,032 Traceback (most recent call last):
2024-01-09T18:12:29,032   File "C:\Users\Iman Babaei\git\testACP\venv\Lib\site-packages\pip\_internal\resolution\resolvelib\resolver.py", line 92, in resolve
2024-01-09T18:12:29,032     result = self._result = resolver.resolve(
2024-01-09T18:12:29,032                             ^^^^^^^^^^^^^^^^^
2024-01-09T18:12:29,032   File "C:\Users\Iman Babaei\git\testACP\venv\Lib\site-packages\pip\_vendor\resolvelib\resolvers.py", line 546, in resolve
2024-01-09T18:12:29,032     state = resolution.resolve(requirements, max_rounds=max_rounds)
2024-01-09T18:12:29,032             ^^^^^^^^^^^^^^^^^^^^^^^^^^^^^^^^^^^^^^^^^^^^^^^^^^^^^^^
2024-01-09T18:12:29,032   File "C:\Users\Iman Babaei\git\testACP\venv\Lib\site-packages\pip\_vendor\resolvelib\resolvers.py", line 399, in resolve
2024-01-09T18:12:29,032     raise ResolutionImpossible(e.criterion.information)
2024-01-09T18:12:29,032 pip._vendor.resolvelib.resolvers.ResolutionImpossible: [RequirementInformation(requirement=SpecifierRequirement('azure-service-connector-passwordless'), parent=None)]
2024-01-09T18:12:29,032 
2024-01-09T18:12:29,032 The above exception was the direct cause of the following exception:
2024-01-09T18:12:29,032 
2024-01-09T18:12:29,032 Traceback (most recent call last):
2024-01-09T18:12:29,032   File "C:\Users\Iman Babaei\git\testACP\venv\Lib\site-packages\pip\_internal\cli\base_command.py", line 180, in exc_logging_wrapper
2024-01-09T18:12:29,032     status = run_func(*args)
2024-01-09T18:12:29,032              ^^^^^^^^^^^^^^^
2024-01-09T18:12:29,032   File "C:\Users\Iman Babaei\git\testACP\venv\Lib\site-packages\pip\_internal\cli\req_command.py", line 248, in wrapper
2024-01-09T18:12:29,032     return func(self, options, args)
2024-01-09T18:12:29,032            ^^^^^^^^^^^^^^^^^^^^^^^^^
2024-01-09T18:12:29,032   File "C:\Users\Iman Babaei\git\testACP\venv\Lib\site-packages\pip\_internal\commands\install.py", line 377, in run
2024-01-09T18:12:29,032     requirement_set = resolver.resolve(
2024-01-09T18:12:29,032                       ^^^^^^^^^^^^^^^^^
2024-01-09T18:12:29,032   File "C:\Users\Iman Babaei\git\testACP\venv\Lib\site-packages\pip\_internal\resolution\resolvelib\resolver.py", line 101, in resolve
2024-01-09T18:12:29,032     raise error from e
2024-01-09T18:12:29,032 pip._internal.exceptions.DistributionNotFound: No matching distribution found for azure-service-connector-passwordless
2024-01-09T18:12:29,165 Remote version of pip: 23.3.2
2024-01-09T18:12:29,166 Local version of pip:  23.2.1
2024-01-09T18:12:29,175 Was pip installed by pip? True
2024-01-09T18:12:29,175 WARNING: [present-rich] UpgradePrompt(old='23.2.1', new='23.3.2')
2024-01-09T18:12:29,185 Removed build tracker: 'C:\\Users\\Iman Babaei\\AppData\\Local\\Temp\\pip-build-tracker-ao4fw73b'
